Workbook

Sheet Overview 
A1: Premium Perfume startup- Individual Data Analytics Assignment Workbook By Harshitaa Sansanwal (MS25MM097)
A3: Topic and Business Objective
A4: Chosen Topic | C4: Validating a premium perfume startup using synthetic consumer data
A5: Business Objective | C5: To test whether a new prermium perfume brand can attract urban young professionals and identify which factors most strongly influence purchase likelihood.
A6: Why Synthetic Data was used | C6: The startup is hypothetical so synthetic data was generated to stimulate realistic consumer behaviour before launch
A7: Dataset Size | C7: 100 customer records with demographic, purchasing and perception variables
A8: Tools Used | C8: Excel- based descriptive analytics, correlation analysis and charts
A9: Main analytical question | C9: Which customer segments, fragrance preferences and behavioural factors suggest the strongest launch potential?
A11: Variables used in the dataset
A12: Column | B12: Meaning | C12: Example
A13: Customer ID | B13: Unique identifier for each sythetic customer | C13: 1
A14: Age | B14: Customer age in years | C14: 27
A15: Gender | B15: Customer gender category | C15: Female
A16: City | B16: Primary city of residence | C16: Delhi
A17: Monthly Income | B17: Estimated monthly income in INR | C17: 62000
A18: Preferred Fragrance | B18: Most preferred fragrance family | C18: Woody
A19: Shopping Channel | B19: Preferred purchase channel | C19: Online
A20: Purchase frequency per year | B20: Perfume purchases per year | C20: 5
A21: Willingness to pay | B21: Amount customer is willing to pay per bottle (INR) | C21: 4800
A22: Influencer Impact | B22: Influence of creators/social media on buying | C22: 4
A23: Brand Awareness | B23: Awareness of perfume fragrance brands(1-5) | C23: 4
A24: Purchase Likelihood | B24: Likelihood of buying from the startup(1-5) | C24: 4
A27: Assignment Workflow Completed in this Workbook
A28: 1. Generated 100 synthetic customer records for a premium perfume startup.
A29: 2. Created a raw dataset containing a few realistic inconsistencies (spacing/casing/missing values).
A30: 3. Cleaned and standardised the data in a separate sheet and documented each cleaning action.
A31: 4. Calculated descriptive statistics, frequency tables, and correlation measures using formulas.
A32: 5. Built charts to explain fragrance demand, channel preference, price potential, and purchase likelihood.
A33: 6. Added ready-to-use report notes summarising the logic, findings, and conclusion.
A36: Key Findings from the Analysis
A37: Higher monthly income is positively associated with willingness to pay for perfume.
A38: Brand awareness and influencer impact both show positive relationships with purchase likelihood.
A39: Offline shopping is slightly more common than online shopping in this synthetic target market.
A40: Floral and woody fragrances emerge as the strongest launch candidates for the startup.

Sheet Raw data
A1: Raw Synthetic Data (with a few realistic inconsistencies)
A3: Customer Id | B3: Age | C3: Gender | D3: City | E3: Monthly Income | F3: Preferred Fragrance | G3: Shopping Channel | H3: Purchase Frequency per year | I3: Willingness to pay | J3: Influencer Impact | K3: Brand Awareness | L3: Purchase likelihood
A4: 1 | B4: 38 | C4: Female | D4: Hyderabad | E4: 91000 | F4: Fresh | G4: Offline | H4: 5 | I4: 5000 | J4: 2 | K4: 4 | L4: 4
A5: 2 | B5: 20 | C5: Female | D5: Bangalore | E5: 54000 | F5: Woody | G5: Offline | H5: 4 | I5: 4800 | J5: 4 | K5: 3 | L5: 5
A6: 3 | B6: 18 | C6: Male | D6: Delhi | E6: 62000 | F6: Woody | G6: Online | H6: 7 | I6: 4700 | J6: 4 | K6: 4 | L6: 4
A7: 4 | B7: 45 | C7: Female | D7: Mumbai | E7: 100000 | F7: Woody | G7: Offline | H7: 4 | I7: 7500 | J7: 2 | K7: 5 | L7: 5
A8: 5 | B8: 37 | C8: Male | D8: Mumbai | E8: 91000 | F8: Woody | G8: Online | H8: 4 | I8: 6000 | J8: 3 | K8: 4 | L8: 5
A9: 6 | B9: 30 | C9: Female | D9: Bangalore | E9: 83000 | F9: Oriental | G9: Online | H9: 3 | I9: 7100 | J9: 2 | K9: 4 | L9: 5
A10: 7 | B10: 23 | C10: Male | D10: Mumbai | E10: 75000 | F10: Citrus | G10: Offline | H10: 4 | I10: 5200 | J10: 4 | K10: 3 | L10: 5
A11: 8 | B11: 42 | C11: Female | D11: Hyderabad | E11: 117000 | F11: fresh | G11: Offline | H11: 4 | I11: 7900 | J11: 2 | K11: 4 | L11: 4
A12: 9 | B12: 33 | C12: Female | D12: Pune | E12: 88000 | F12: Citrus | G12: Online | H12: 6 | I12: 5900 | J12: 2 | K12: 4 | L12: 5
A13: 10 | B13: 30 | C13: Female | D13: Pune | E13: 73000 | F13: Floral | G13: Online | H13: 3 | I13: 5200 | J13: 3 | K13: 3 | L13: 5
A14: 11 | B14: 31 | C14: Male | D14: Mumbai | E14: 93000 | F14: Fresh | G14: Online | H14: 3 | I14: 5600 | J14: 4 | K14: 5 | L14: 5
A15: 12 | B15: 35 | C15: Male | D15: hyderabad | E15: 89000 | F15: Fresh | G15: Offline | H15: 3 | I15: 6300 | J15: 2 | K15: 3 | L15: 5
... A17: 14 | B17: 42 | C17: Male | D17: Pune | E17: 109000 | F17: Fresh | G17: Online | H17: 5 | I17: 7700 | J17: 2 | K17: 5 | L17: 5
A18: 15 | B18: 25 | C18: Male | D18: Pune | E18: 62000 | F18: Citrus | G18: Offline | H18: 4 | I18: 3700 | J18: 4 | L18: 5
A19: 16 | B19: 35 | C19: Female | D19: Bangalore | E19: 100000 | F19: Oriental | G19: Online | H19: 5 | I19: 7000 | J19: 2 | K19: 4 | L19: 5
A20: 17 | B20: 39 | C20: Male | D20: Mumbai | E20: 105000 | F20: Floral | G20: Online | H20: 4 | I20: 6800 | J20: 2 | K20: 4 | L20: 5
A21: 18 | B21: 18 | C21: Female | D21: Bangalore | E21: 57000 | F21: Citrus | G21: Online | H21: 6 | I21: 3500 | J21: 4 | K21: 3 | L21: 4
A22: 19 | B22: 22 | C22: Male | D22: Pune | E22: 72000 | F22: Woody | G22: Offline | H22: 6 | I22: 5200 | J22: 4 | K22: 4 | L22: 5
A23: 20 | B23: 31 | C23: Female | D23: Hyderabad | E23: 93000 | F23: Oriental | G23: OFFLINE | H23: 1 | I23: 7800 | J23: 3 | K23: 3 | L23: 4
A24: 21 | B24: 24 | C24: Male | D24: Delhi | E24: 65000 | F24: Woody | G24: Online | H24: 4 | I24: 6300 | J24: 3 | K24: 4 | L24: 4
A25: 22 | B25: 35 | C25: Male | D25: Pune | E25: 102000 | F25: Woody | G25: Online | H25: 3 | I25: 7200 | J25: 3 | K25: 4 | L25: 5
A26: 23 | B26: 18 | C26: Other | D26: Mumbai | E26: 76000 | F26: Oriental | G26: Online | H26: 7 | I26: 7500 | J26: 5 | K26: 4 | L26: 5
A27: 24 | B27: 27 | C27: Female | D27: Delhi | E27: 89000 | F27: Citrus | G27: Offline | H27: 3 | I27: 5400 | J27: 3 | K27: 3 | L27: 4
A28: 25 | B28: 34 | C28: Female | D28: Delhi | E28: 97000 | F28: Fresh | G28: Offline | H28: 2 | I28: 6000 | J28: 2 | K28: 3 | L28: 4
A29: 26 | B29: 19 | C29: Male | D29: Mumbai | E29: 71000 | F29: Oriental | G29: Online | H29: 4 | I29: 5900 | J29: 4 | K29: 3 | L29: 4
A30: 27 | B30: 22 | C30: Male | D30: Mumbai | E30: 68000 | F30: Citrus | G30: Offline | H30: 2 | I30: 4400 | J30: 4 | K30: 2 | L30: 3
A31: 28 | B31: 24 | C31: Female | D31: Delhi | E31: 71000 | F31: Floral | G31: Offline | H31: 4 | I31: 5700 | J31: 4 | K31: 3 | L31: 5
A32: 29 | B32: 43 | C32: Male | D32: Delhi | E32: 120000 | F32: Fresh | G32: Offline | H32: 1 | I32: 6600 | K32: 3 | L32: 5
A33: 30 | B33: 41 | C33: Male | D33: Mumbai | E33: 112000 | F33: Fresh | G33: Offline | H33: 5 | I33: 6700 | J33: 1 | K33: 4 | L33: 4
A34: 31 | B34: 45 | C34: Female | D34: Bangalore | E34: 125000 | F34: Citrus | G34: Online | H34: 4 | I34: 6800 | J34: 1 | K34: 5 | L34: 5
A35: 32 | B35: 35 | C35: Male | D35: Bangalore | E35: 84000 | F35: Citrus | G35: Offline | H35: 4 | I35: 5900 | J35: 2 | K35: 4 | L35: 4
A36: 33 | B36: 22 | C36: Female | D36: Delhi | E36: 68000 | F36: Fresh | G36: Offline | H36: 4 | I36: 4500 | J36: 4 | K36: 4 | L36: 5
A37: 34 | B37: 29 | C37: Male | D37: Pune | E37: 80000 | F37: Woody | G37: Offline | H37: 4 | I37: 5800 | J37: 4 | K37: 4 | L37: 5
A38: 35 | B38: 18 | C38: Female | D38: Pune | E38: 72000 | F38: Oriental | G38: Offline | H38: 4 | I38: 6300 | J38: 5 | K38: 4 | L38: 5
A39: 36 | B39: 21 | C39: Female | D39: Delhi | E39: 69000 | F39: Floral | G39: Offline | H39: 3 | I39: 5400 | J39: 3 | K39: 3 | L39: 4
A40: 37 | B40: 39 | C40: Female | D40: mumbai | E40: 90000 | F40: Woody | G40: Online | H40: 5 | I40: 7500 | J40: 3 | K40: 4 | L40: 5
A41: 38 | B41: 21 | C41: Male | D41: Mumbai | E41: 75000 | F41: Woody | G41: Online | H41: 5 | I41: 6600 | J41: 5 | K41: 3 | L41: 5
A42: 39 | B42: 34 | C42: Female | D42: Pune | E42: 81000 | F42: Fresh | G42: Offline | H42: 2 | I42: 4900 | J42: 2 | K42: 2 | L42: 3
...

Sheet Purchase likelihood
A1: Purchase Likelihood
A3: Mean | B3: 4.53
A4: Standard Error | B4: 0.061059666
A5: Median | B5: 5
A6: Mode | B6: 5
A7: Standard Deviation | B7: 0.61059666
A8: Sample Variance | B8: 0.37282828
A9: Kurtosis | B9: -0.11902385
A10: Skewness | B10: -0.93155147
A11: Range | B11: 2
A12: Minimum | B12: 3
A13: Maximum | B13: 5
A14: Sum | B14: 453
... A17: Smallest(2) | B17: 3

Sheet Purchase frequency per year
A1: Purchase frequency per year
A3: Mean | B3: 4.08
A4: Standard Error | B4: 0.14817407
A5: Median | B5: 4
A6: Mode | B6: 4
A7: Standard Deviation | B7: 1.4817407
A8: Sample Variance | B8: 2.1955556
A9: Kurtosis | B9: -0.42972633
A10: Skewness | B10: -0.026035569
A11: Range | B11: 6
A12: Minimum | B12: 1
A13: Maximum | B13: 7
A14: Sum | B14: 408
... A17: Smallest(2) | B17: 1

Sheet Willingness to pay
A1: Willingness to pay
A3: Mean | B3: 6156
A4: Standard Error | B4: 111.9733
A5: Median | B5: 6300
A6: Mode | B6: 6600
A7: Standard Deviation | B7: 1119.733
A8: Sample Variance | B8: 1253802
A9: Kurtosis | B9: -0.062589724
A10: Skewness | B10: -0.35302305
A11: Range | B11: 5200
A12: Minimum | B12: 3200
A13: Maximum | B13: 8400
A14: Sum | B14: 615600
... A17: Smallest(2) | B17: 3500

Sheet Influencer impact
A1: Influencer impact
A3: Mean | B3: 2.86
A4: Standard Error | B4: 0.10152374
A5: Median | B5: 3
A6: Mode | B6: 2
A7: Standard Deviation | B7: 1.0152374
A8: Sample Variance | B8: 1.0307071
A9: Kurtosis | B9: -0.61244101
A10: Skewness | B10: 0.16874217
A11: Range | B11: 4
A12: Minimum | B12: 1
A13: Maximum | B13: 5
A14: Sum | B14: 286
... A17: Smallest(2) | B17: 1

Sheet Brand Awareness
A1: Brand Awareness
A3: Mean | B3: 3.72
A4: Standard Error | B4: 0.066787769
A5: Median | B5: 4
A6: Mode | B6: 4
A7: Standard Deviation | B7: 0.66787769
A8: Sample Variance | B8: 0.44606061
A9: Kurtosis | B9: 0.094508326
A10: Skewness | B10: -0.23216478
A11: Range | B11: 3
A12: Minimum | B12: 2
A13: Maximum | B13: 5
A14: Sum | B14: 372
... A17: Smallest(2) | B17: 2

Sheet Cleaned data
A1: Cleaned and Standardised Dataset Used for Analysis
A3: Customer Id | B3: Age | C3: Gender | D3: City | E3: Monthly Income | F3: Preferred Fragrance | G3: Shopping Channel | H3: Purchase Frequency per year | I3: Willingness to pay | J3: Influencer Impact | K3: Brand Awareness | L3: Purchase likelihood | M3: Age group | N3: Income segment
A4: 1 | B4: 38 | C4: Female | D4: Hyderabad | E4: 91000 | F4: Fresh | G4: Offline | H4: 5 | I4: 5000 | J4: 2 | K4: 4 | L4: 4 | M4: =IF(B4<=24,"18-24",IF(B4<=30,"25-30",IF(B4<=36,"31-36","37-45"))) -> 37-45 | N4: =IF(E4<50000,"Low",IF(E4<90000,"Middle","High")) -> High
A5: 2 | B5: 20 | C5: Female | D5: Bangalore | E5: 54000 | F5: Woody | G5: Offline | H5: 4 | I5: 4800 | J5: 4 | K5: 3 | L5: 5 | M5: =IF(B5<=24,"18-24",IF(B5<=30,"25-30",IF(B5<=36,"31-36","37-45"))) -> 18-24 | N5: =IF(E5<50000,"Low",IF(E5<90000,"Middle","High")) -> Middle
A6: 3 | B6: 18 | C6: Male | D6: Delhi | E6: 62000 | F6: Woody | G6: Online | H6: 7 | I6: 4700 | J6: 4 | K6: 4 | L6: 4 | M6: =IF(B6<=24,"18-24",IF(B6<=30,"25-30",IF(B6<=36,"31-36","37-45"))) -> 18-24 | N6: =IF(E6<50000,"Low",IF(E6<90000,"Middle","High")) -> Middle
A7: 4 | B7: 45 | C7: Female | D7: Mumbai | E7: 100000 | F7: Woody | G7: Offline | H7: 4 | I7: 7500 | J7: 2 | K7: 5 | L7: 5 | M7: =IF(B7<=24,"18-24",IF(B7<=30,"25-30",IF(B7<=36,"31-36","37-45"))) -> 37-45 | N7: =IF(E7<50000,"Low",IF(E7<90000,"Middle","High")) -> High
A8: 5 | B8: 37 | C8: Male | D8: Mumbai | E8: 91000 | F8: Woody | G8: Online | H8: 4 | I8: 6000 | J8: 3 | K8: 4 | L8: 5 | M8: =IF(B8<=24,"18-24",IF(B8<=30,"25-30",IF(B8<=36,"31-36","37-45"))) -> 37-45 | N8: =IF(E8<50000,"Low",IF(E8<90000,"Middle","High")) -> High
A9: 6 | B9: 30 | C9: Female | D9: Bangalore | E9: 83000 | F9: Oriental | G9: Online | H9: 3 | I9: 7100 | J9: 2 | K9: 4 | L9: 5 | M9: =IF(B9<=24,"18-24",IF(B9<=30,"25-30",IF(B9<=36,"31-36","37-45"))) -> 25-30 | N9: =IF(E9<50000,"Low",IF(E9<90000,"Middle","High")) -> Middle
A10: 7 | B10: 23 | C10: Male | D10: Mumbai | E10: 75000 | F10: Citrus | G10: Offline | H10: 4 | I10: 5200 | J10: 4 | K10: 3 | L10: 5 | M10: =IF(B10<=24,"18-24",IF(B10<=30,"25-30",IF(B10<=36,"31-36","37-45"))) -> 18-24 | N10: =IF(E10<50000,"Low",IF(E10<90000,"Middle","High")) -> Middle
A11: 8 | B11: 42 | C11: Female | D11: Hyderabad | E11: 117000 | F11: Fresh | G11: Offline | H11: 4 | I11: 7900 | J11: 2 | K11: 4 | L11: 4 | M11: =IF(B11<=24,"18-24",IF(B11<=30,"25-30",IF(B11<=36,"31-36","37-45"))) -> 37-45 | N11: =IF(E11<50000,"Low",IF(E11<90000,"Middle","High")) -> High
A12: 9 | B12: 33 | C12: Female | D12: Pune | E12: 88000 | F12: Citrus | G12: Online | H12: 6 | I12: 5900 | J12: 2 | K12: 4 | L12: 5 | M12: =IF(B12<=24,"18-24",IF(B12<=30,"25-30",IF(B12<=36,"31-36","37-45"))) -> 31-36 | N12: =IF(E12<50000,"Low",IF(E12<90000,"Middle","High")) -> Middle
A13: 10 | B13: 30 | C13: Female | D13: Pune | E13: 73000 | F13: Floral | G13: Online | H13: 3 | I13: 5200 | J13: 3 | K13: 3 | L13: 5 | M13: =IF(B13<=24,"18-24",IF(B13<=30,"25-30",IF(B13<=36,"31-36","37-45"))) -> 25-30 | N13: =IF(E13<50000,"Low",IF(E13<90000,"Middle","High")) -> Middle
A14: 11 | B14: 31 | C14: Male | D14: Mumbai | E14: 93000 | F14: Fresh | G14: Online | H14: 3 | I14: 5600 | J14: 4 | K14: 5 | L14: 5 | M14: =IF(B14<=24,"18-24",IF(B14<=30,"25-30",IF(B14<=36,"31-36","37-45"))) -> 31-36 | N14: =IF(E14<50000,"Low",IF(E14<90000,"Middle","High")) -> High
A15: 12 | B15: 35 | C15: Male | D15: Hyderabad | E15: 89000 | F15: Fresh | G15: Offline | H15: 3 | I15: 6300 | J15: 2 | K15: 3 | L15: 5 | M15: =IF(B15<=24,"18-24",IF(B15<=30,"25-30",IF(B15<=36,"31-36","37-45"))) -> 31-36 | N15: =IF(E15<50000,"Low",IF(E15<90000,"Middle","High")) -> Middle
... A103: 100 | B103: 43 | C103: Male | D103: Delhi | E103: 106000 | F103: Oriental | G103: Offline | H103: 4 | I103: 8100 | J103: 1 | K103: 4 | L103: 4 | M103: =IF(B103<=24,"18-24",IF(B103<=30,"25-30",IF(B103<=36,"31-36","37-45"))) -> 37-45 | N103: =IF(E103<50000,"Low",IF(E103<90000,"Middle","High")) -> High
A105: The raw sheet contains a few deliberate inconsistencies to demonstrate a proper data-cleaning workflow. The cleaned sheet standardises text values and fills missing numeric values using reasonable replacement values. This makes the data ready for descriptive analytics, EDA, and correlation analysis.
B108: Key KPIs | E108: Fragrance Preference Frequency | H108: Shopping Channel Frequency | K108: Purchase Likelihood by Age Frequency
B109: Total customers | C109: =COUNT(A4:A103) -> 100 | K109: 18-24 | L109: =COUNTIF(M4:M103,M96) -> 26
B110: Average age | C110: =ROUND(AVERAGE(B4:B103),) -> 31 | E110: Floral | F110: =COUNTIF(F4:F103,F16) -> 20 | H110: Online | I110: =COUNTIF(G4:G103,G85) -> 40 | K110: 25-30 | L110: =COUNTIF(M4:M103,M99) -> 18
B111: Average monthly income (INR) | C111: =ROUND(AVERAGE(E4:E103),) -> 87840 | E111: Woody | F111: =COUNTIF(F4:F103,F101) -> 31 | H111: Offline | I111: =COUNTIF(G4:G103,G92) -> 60 | K111: 31-36 | L111: =COUNTIF(M4:M103,M88) -> 25
B112: Average willingness to pay (INR) | C112: =ROUND(AVERAGE(I4:I103),) -> 6156 | E112: Citrus | F112: =COUNTIF(F4:F103,F90) -> 14 | K112: 37-45 | L112: =COUNTIF(M4:M103,M100) -> 31
B113: Average purchase likelihood | C113: =ROUND(AVERAGE(L4:L103),) -> 5 | E113: Oriental | F113: =COUNTIF(F4:F103,F103) -> 17
B114: Most preferred fragrance | C114: Woody | E114: Fresh | F114: =COUNTIF(F4:F103,F100) -> 18
B115: Most common shopping channel | C115: Offline
B118: Avg Willingness to Pay by City
B119: Delhi | C119: =ROUND(AVERAGEIF(D4:D103,D31,I4:I103),0) -> 6005
B120: Mumbai | C120: =ROUND(AVERAGEIF(D4:D103,D95,I4:I103),0) -> 6424
B121: Bangalore | C121: =ROUND(AVERAGEIF(D4:D103,D96,I4:I103),0) -> 6241
B122: Hyderabad | C122: =ROUND(AVERAGEIF(D4:D103,D83,I4:I103),0) -> 5950
B123: Pune | C123: =ROUND(AVERAGEIF(D4:D103,D101,I4:I103),0) -> 5911

Sheet Descriptive stats
A1: Descriptive Analytics and EDA Summary
A3: Key KPIs | D3: Purchase Likelihood | G3: Purchase frequency per year
A4: Total customers | B4: ='Cleaned data'!C109 -> 100
A5: Average age | B5: ='Cleaned data'!C110 -> 31 | D5: Mean | E5: 4.53 | G5: Mean | H5: 4.08
A6: Average monthly income (INR) | B6: ='Cleaned data'!C111 -> 87840 | D6: Standard Error | E6: 0.061059666 | G6: Standard Error | H6: 0.14817407
A7: Average willingness to pay (INR) | B7: ='Cleaned data'!C112 -> 6156 | D7: Median | E7: 5 | G7: Median | H7: 4
A8: Average purchase likelihood | B8: ='Cleaned data'!C113 -> 5 | D8: Mode | E8: 5 | G8: Mode | H8: 4
A9: Most preferred fragrance | B9: Woody | D9: Standard Deviation | E9: 0.61059666 | G9: Standard Deviation | H9: 1.4817407
A10: Most common shopping channel | B10: Offline | D10: Sample Variance | E10: 0.37282828 | G10: Sample Variance | H10: 2.1955556
D11: Kurtosis | E11: -0.11902385 | G11: Kurtosis | H11: -0.42972633
D12: Skewness | E12: -0.93155147 | G12: Skewness | H12: -0.026035569
D13: Range | E13: 2 | G13: Range | H13: 6
D14: Minimum | E14: 3 | G14: Minimum | H14: 1
D15: Maximum | E15: 5 | G15: Maximum | H15: 7
D16: Sum | E16: 453 | G16: Sum | H16: 408
D17: Count | E17: 100 | G17: Count | H17: 100
D18: Largest(2) | E18: 5 | G18: Largest(2) | H18: 7
D19: Smallest(2) | E19: 3 | G19: Smallest(2) | H19: 1
A23: Willingness to pay | D23: Influencer impact | G23: Brand Awareness
A25: Mean | B25: 6156 | D25: Mean | E25: 2.86 | G25: Mean | H25: 3.72
A26: Standard Error | B26: 111.9733 | D26: Standard Error | E26: 0.10152374 | G26: Standard Error | H26: 0.066787769
A27: Median | B27: 6300 | D27: Median | E27: 3 | G27: Median | H27: 4
A28: Mode | B28: 6600 | D28: Mode | E28: 2 | G28: Mode | H28: 4
A29: Standard Deviation | B29: 1119.733 | D29: Standard Deviation | E29: 1.0152374 | G29: Standard Deviation | H29: 0.66787769
A30: Sample Variance | B30: 1253802 | D30: Sample Variance | E30: 1.0307071 | G30: Sample Variance | H30: 0.44606061
A31: Kurtosis | B31: -0.062589724 | D31: Kurtosis | E31: -0.61244101 | G31: Kurtosis | H31: 0.094508326
A32: Skewness | B32: -0.35302305 | D32: Skewness | E32: 0.16874217 | G32: Skewness | H32: -0.23216478
A33: Range | B33: 5200 | D33: Range | E33: 4 | G33: Range | H33: 3
A34: Minimum | B34: 3200 | D34: Minimum | E34: 1 | G34: Minimum | H34: 2
A35: Maximum | B35: 8400 | D35: Maximum | E35: 5 | G35: Maximum | H35: 5
A36: Sum | B36: 615600 | D36: Sum | E36: 286 | G36: Sum | H36: 372
... A39: Smallest(2) | B39: 3500 | D39: Smallest(2) | E39: 1 | G39: Smallest(2) | H39: 2
A42: Fragrance Preference Frequency | D42: Shopping Channel Frequency | G42: Purchase Likelihood by Age Frequency
G43: 18-24 | H43: ='Cleaned data'!L109 -> 26
A44: Floral | B44: ='Cleaned data'!F110 -> 20 | D44: Online | E44: ='Cleaned data'!I110 -> 40 | G44: 25-30 | H44: ='Cleaned data'!L110 -> 18
A45: Woody | B45: ='Cleaned data'!F111 -> 31 | D45: Offline | E45: ='Cleaned data'!I111 -> 60 | G45: 31-36 | H45: ='Cleaned data'!L111 -> 25
A46: Citrus | B46: ='Cleaned data'!F112 -> 14 | G46: 37-45 | H46: ='Cleaned data'!L112 -> 31
A47: Oriental | B47: ='Cleaned data'!F113 -> 17
A48: Fresh | B48: ='Cleaned data'!F114 -> 18
D50: Avg Willingness to Pay by City
...

Sheet Correlation
A1: Correlation Analysis
A3: Correlation matrix using Excel CORREL formulas
B5: Monthly Income | C5: Purchase Frequency per year | D5: Willingness to pay | E5: Influencer impact | F5: Brand Awareness | G5: Purchase Likelihood
A6: Monthly Income | B6: =CORREL('Cleaned data'!E4:E103,'Cleaned data'!E4:E103) -> 1
A7: Purchase Frequency per year | B7: =CORREL('Cleaned data'!E4:E103,'Cleaned data'!H4:H103) -> -0.27957139 | C7: =CORREL('Cleaned data'!H4:H103,'Cleaned data'!H4:H103) -> 1
A8: Willingness to pay | B8: =CORREL('Cleaned data'!E4:E103,'Cleaned data'!I4:I103) -> 0.69700971 | C8: =CORREL('Cleaned data'!H4:H103,'Cleaned data'!I4:I103) -> -0.052040639 | D8: =CORREL('Cleaned data'!I4:I103,'Cleaned data'!I4:I103) -> 1
A9: Influencer impact | B9: =CORREL('Cleaned data'!E4:E103,'Cleaned data'!J4:J103) -> -0.73657077 | C9: =CORREL('Cleaned data'!H4:H103,'Cleaned data'!J4:J103) -> 0.26939274 | D9: =CORREL('Cleaned data'!I4:I103,'Cleaned data'!J4:J103) -> -0.40532174 | E9: =CORREL('Cleaned data'!J4:J103,'Cleaned data'!J4:J103) -> 1
A10: Brand Awareness | B10: =CORREL('Cleaned data'!E4:E103,'Cleaned data'!K4:K103) -> 0.37787498 | C10: =CORREL('Cleaned data'!H4:H103,'Cleaned data'!K4:K103) -> 0.31886487 | D10: =CORREL('Cleaned data'!I4:I103,'Cleaned data'!K4:K103) -> 0.49796976 | E10: =CORREL('Cleaned data'!J4:J103,'Cleaned data'!K4:K103) -> -0.20736692 | F10: =CORREL('Cleaned data'!K4:K103,'Cleaned data'!K4:K103) -> 1
A11: Purchase Likelihood | B11: =CORREL('Cleaned data'!E4:E103,'Cleaned data'!L4:L103) -> -0.01827343 | C11: =CORREL('Cleaned data'!H4:H103,'Cleaned data'!L4:L103) -> 0.22060995 | D11: =CORREL('Cleaned data'!I4:I103,'Cleaned data'!L4:L103) -> 0.26344864 | E11: =CORREL('Cleaned data'!J4:J103,'Cleaned data'!L4:L103) -> 0.23496762 | F11: =CORREL('Cleaned data'!K4:K103,'Cleaned data'!L4:L103) -> 0.49142259 | G11: =CORREL('Cleaned data'!L4:L103,'Cleaned data'!L4:L103) -> 1
A13: Interpretations
A14: Strong positive | B14: Values closer to +1.000 show a strong direct relationship.
A15: Weak/Neutral | B15: Values near 0.000 show little linear relationship.
A16: Use | B16: The most important relationships are income vs willingness to pay and awareness/influencer impact vs purchase likelihood.

Sheet Graphs
A1: Graphs with Business Interpretation
A3: All charts below are based on the cleaned analytical dataset
A7: 1 | H7: 2
A23: Bar chart interpretation: Floral and woody fragrances have the highest counts, so these are the strongest candidates for the startup’s first product line.
I26: Pie chart interpretation: Offline shopping is slightly higher than online shopping, so an omnichannel launch with strong digital promotion would fit this market.
A31: 3
I32: 4
K56: Interpretation: Customers with higher influencer impact tend to show higher purchase likelihood, supporting influencer-led promotion.
B59: Age-group interpretation: Mid-young adult groups show strong buying interest, making them a practical primary target segment.
D66: 5
C86: Interpretation: The upward pattern suggests that higher-income customers are generally willing to pay more for perfume.

Sheet Report
A1: Report
A3: Introduction
A4: This project evaluates the business potential of a premium perfume startup using synthetic consumer data. Because the startup is hypothetical and no historical data exists, a synthetic dataset was created to simulate realistic customer demographics, income levels, fragrance preferences, purchase behaviour, and purchase intention.
A8: Business objective
A9: The objective is to understand whether a premium perfume brand can attract enough demand in an urban target market and to identify the variables that most strongly influence willingness to pay and purchase likelihood.
A13: Synthetic data generation
A14: A dataset of 100 customer records was generated. The variables were designed to reflect likely market conditions for a perfume startup, including age, city, monthly income, preferred fragrance family, shopping channel, influencer impact, brand awareness, willingness to pay, and purchase likelihood.
A18: Data cleaning and transformation
A19: The raw dataset was reviewed for formatting inconsistencies and missing values. Text labels were standardised by correcting spacing and letter case. Missing Brand Awareness values were replaced with the median value of 4, and missing Influencer Impact values were replaced with the median value of 3. Two derived variables, Age Group and Income Segment, were added for clearer analysis.
A23: Descriptive analytics and EDA
A24: Descriptive statistics show a target market with moderate to high purchasing power. Frequency analysis suggests that floral and woody fragrances are the most preferred categories. Shopping-channel analysis shows slightly higher offline buying, which supports an omnichannel strategy with strong digital promotion. Average willingness to pay supports a premium-but-accessible pricing strategy.
A28: Correlation insight
... A34: Overall, the synthetic analysis supports the viability of the perfume startup idea. The findings suggest that the business should focus on strong fragrance positioning around floral and woody families, combined with an omnichannel sales approach and brand-building efforts targeted at urban consumers with medium to high income.
